<robot name="panda">
  <link name="panda_link0">
  	<inertial>
      <origin rpy="0 0 0" xyz="0 0 0.05" />
       <mass value="2.9" />
       <inertia ixx="0.1" ixy="0" ixz="0" iyy="0.1" iyz="0" izz="0.1" />
    </inertial>
    <visual>
      <geometry>
        <mesh filename="hd_meshes/visual/link0.dae" />
      </geometry>
      <material name="panda_white">
    		<color rgba="1. 1. 1. 1." />
  		</material>
    </visual>
    <collision>
      <geometry>
        <mesh filename="hd_meshes/collision/link0.vhacd.00.obj" />
      </geometry>
      <material name="panda_white" />
    </collision>
  <collision>
      <geometry>
        <mesh filename="hd_meshes/collision/link0.vhacd.01.obj" />
      </geometry>
      <material name="panda_white" />
    </collision>
  <collision>
      <geometry>
        <mesh filename="hd_meshes/collision/link0.vhacd.02.obj" />
      </geometry>
      <material name="panda_white" />
    </collision>
  <collision>
      <geometry>
        <mesh filename="hd_meshes/collision/link0.vhacd.03.obj" />
      </geometry>
      <material name="panda_white" />
    </collision>
  </link>
  <link name="panda_link1">
  	<inertial>
      <origin rpy="0 0 0" xyz="0 -0.04 -0.05"/>
       <mass value="2.7"/>
       <inertia ixx="0.1" ixy="0" ixz="0" iyy="0.1" iyz="0" izz="0.1"/>
    </inertial>
    <visual>
      <geometry>
        <mesh filename="hd_meshes/visual/link1.dae" />
      </geometry>
      <material name="panda_white" />
    </visual>
    <collision>
      <geometry>
        <mesh filename="hd_meshes/collision/link1.vhacd.00.obj" />
      </geometry>
      <material name="panda_white" />
    </collision>
  <collision>
      <geometry>
        <mesh filename="hd_meshes/collision/link1.vhacd.01.obj" />
      </geometry>
      <material name="panda_white" />
    </collision>
  </link>
  <joint name="panda_joint1" type="revolute">
    <safety_controller k_position="100.0" k_velocity="40.0" soft_lower_limit="-2.8973" soft_upper_limit="2.8973" />
    <origin rpy="0 0 0" xyz="0 0 0.333" />
    <parent link="panda_link0" />
    <child link="panda_link1" />
    <axis xyz="0 0 1" />
    <limit effort="87" lower="-2.8973" upper="2.8973" velocity="2.1750" />
  </joint>
  <link name="panda_link2">
  	<inertial>
      <origin rpy="0 0 0" xyz="0 -0.04 0.06" />
       <mass value="2.73" />
       <inertia ixx="0.1" ixy="0" ixz="0" iyy="0.1" iyz="0" izz="0.1" />
    </inertial>
    <visual>
      <geometry>
        <mesh filename="hd_meshes/visual/link2.dae" />
      </geometry>
      <material name="panda_white" />
    </visual>
    <collision>
      <geometry>
        <mesh filename="hd_meshes/collision/link2.vhacd.00.obj" />
      </geometry>
      <material name="panda_white" />
    </collision>
  <collision>
      <geometry>
        <mesh filename="hd_meshes/collision/link2.vhacd.01.obj" />
      </geometry>
      <material name="panda_white" />
    </collision>
  <collision>
      <geometry>
        <mesh filename="hd_meshes/collision/link2.vhacd.02.obj" />
      </geometry>
      <material name="panda_white" />
    </collision>
  </link>
  <joint name="panda_joint2" type="revolute">
    <safety_controller k_position="100.0" k_velocity="40.0" soft_lower_limit="-1.7628" soft_upper_limit="1.7628" />
    <origin rpy="-1.57079632679 0 0" xyz="0 0 0" />
    <parent link="panda_link1" />
    <child link="panda_link2" />
    <axis xyz="0 0 1" />
    <limit effort="87" lower="-1.7628" upper="1.7628" velocity="2.1750" />
  </joint>
  <link name="panda_link3">
	  <inertial>
      <origin rpy="0 0 0" xyz="0.01 0.01 -0.05" />
       <mass value="2.04" />
       <inertia ixx="0.1" ixy="0" ixz="0" iyy="0.1" iyz="0" izz="0.1" />
    </inertial>
    <visual>
      <geometry>
        <mesh filename="hd_meshes/visual/link3.dae" />
      </geometry>
      <material name="panda_red">
    		<color rgba="1. 1. 1. 1." />
  		</material>
    </visual>
    <collision>
      <geometry>
        <mesh filename="hd_meshes/collision/link3.vhacd.00.obj" />
      </geometry>
    </collision>
  <collision>
      <geometry>
        <mesh filename="hd_meshes/collision/link3.vhacd.01.obj" />
      </geometry>
    </collision>
  <collision>
      <geometry>
        <mesh filename="hd_meshes/collision/link3.vhacd.02.obj" />
      </geometry>
    </collision>
  <collision>
      <geometry>
        <mesh filename="hd_meshes/collision/link3.vhacd.03.obj" />
      </geometry>
    </collision>
  </link>
  <joint name="panda_joint3" type="revolute">
    <safety_controller k_position="100.0" k_velocity="40.0" soft_lower_limit="-2.8973" soft_upper_limit="2.8973" />
    <origin rpy="1.57079632679 0 0" xyz="0 -0.316 0" />
    <parent link="panda_link2" />
    <child link="panda_link3" />
    <axis xyz="0 0 1" />
    <limit effort="87" lower="-2.8973" upper="2.8973" velocity="2.1750" />
  </joint>
  <link name="panda_link4">
  	<inertial>
      <origin rpy="0 0 0" xyz="-0.03 0.03 0.02" />
       <mass value="2.08" />
       <inertia ixx="0.1" ixy="0" ixz="0" iyy="0.1" iyz="0" izz="0.1" />
    </inertial>
    <visual>
      <geometry>
        <mesh filename="hd_meshes/visual/link4.dae" />
      </geometry>
      <material name="panda_white" />
    </visual>
    <collision>
      <geometry>
        <mesh filename="hd_meshes/collision/link4.vhacd.00.obj" />
      </geometry>
      <material name="panda_white" />
    </collision>
  <collision>
      <geometry>
        <mesh filename="hd_meshes/collision/link4.vhacd.01.obj" />
      </geometry>
      <material name="panda_white" />
    </collision>
  <collision>
      <geometry>
        <mesh filename="hd_meshes/collision/link4.vhacd.02.obj" />
      </geometry>
      <material name="panda_white" />
    </collision>
  <collision>
      <geometry>
        <mesh filename="hd_meshes/collision/link4.vhacd.03.obj" />
      </geometry>
      <material name="panda_white" />
    </collision>
  </link>
  <joint name="panda_joint4" type="revolute">
    <safety_controller k_position="100.0" k_velocity="40.0" soft_lower_limit="-3.0718" soft_upper_limit="-0.0698" />
    <origin rpy="1.57079632679 0 0" xyz="0.0825 0 0" />
    <parent link="panda_link3" />
    <child link="panda_link4" />
    <axis xyz="0 0 1" />
    <limit effort="87" lower="-3.0718" upper="-0.0698" velocity="2.1750" />
  </joint>
  <link name="panda_link5">
  	<inertial>
      <origin rpy="0 0 0" xyz="0 0.04 -0.12" />
       <mass value="3" />
       <inertia ixx="0.1" ixy="0" ixz="0" iyy="0.1" iyz="0" izz="0.1" />
    </inertial>
    <visual>
      <geometry>
        <mesh filename="hd_meshes/visual/link5.dae" />
      </geometry>
      <material name="panda_white" />
    </visual>
    <collision>
      <geometry>
        <mesh filename="hd_meshes/collision/link5.vhacd.00.obj" />
      </geometry>
      <material name="panda_white" />
    </collision>
  <collision>
      <geometry>
        <mesh filename="hd_meshes/collision/link5.vhacd.01.obj" />
      </geometry>
      <material name="panda_white" />
    </collision>
  <collision>
      <geometry>
        <mesh filename="hd_meshes/collision/link5.vhacd.02.obj" />
      </geometry>
      <material name="panda_white" />
    </collision>
  <collision>
      <geometry>
        <mesh filename="hd_meshes/collision/link5.vhacd.03.obj" />
      </geometry>
      <material name="panda_white" />
    </collision>
  </link>
  <joint name="panda_joint5" type="revolute">
    <safety_controller k_position="100.0" k_velocity="40.0" soft_lower_limit="-2.8973" soft_upper_limit="2.8973" />
    <origin rpy="-1.57079632679 0 0" xyz="-0.0825 0.384 0" />
    <parent link="panda_link4" />
    <child link="panda_link5" />
    <axis xyz="0 0 1" />
    <limit effort="12" lower="-2.8973" upper="2.8973" velocity="2.6100" />
  </joint>
  <link name="panda_link6">
  	<inertial>
      <origin rpy="0 0 0" xyz="0.04 0 0" />
       <mass value="1.3" />
       <inertia ixx="0.1" ixy="0" ixz="0" iyy="0.1" iyz="0" izz="0.1" />
    </inertial>
    <visual>
      <geometry>
        <mesh filename="hd_meshes/visual/link6.dae" />
      </geometry>
      <material name="panda_white" />
    </visual>
    <collision>
      <geometry>
        <mesh filename="hd_meshes/collision/link6.vhacd.00.obj" />
      </geometry>
      <material name="panda_white" />
    </collision>
  <collision>
      <geometry>
        <mesh filename="hd_meshes/collision/link6.vhacd.01.obj" />
      </geometry>
      <material name="panda_white" />
    </collision>
  <collision>
      <geometry>
        <mesh filename="hd_meshes/collision/link6.vhacd.02.obj" />
      </geometry>
      <material name="panda_white" />
    </collision>
  <collision>
      <geometry>
        <mesh filename="hd_meshes/collision/link6.vhacd.03.obj" />
      </geometry>
      <material name="panda_white" />
    </collision>
  <collision>
      <geometry>
        <mesh filename="hd_meshes/collision/link6.vhacd.04.obj" />
      </geometry>
      <material name="panda_white" />
    </collision>
  <collision>
      <geometry>
        <mesh filename="hd_meshes/collision/link6.vhacd.05.obj" />
      </geometry>
      <material name="panda_white" />
    </collision>
  <collision>
      <geometry>
        <mesh filename="hd_meshes/collision/link6.vhacd.06.obj" />
      </geometry>
      <material name="panda_white" />
    </collision>
  <collision>
      <geometry>
        <mesh filename="hd_meshes/collision/link6.vhacd.07.obj" />
      </geometry>
      <material name="panda_white" />
    </collision>
  <collision>
      <geometry>
        <mesh filename="hd_meshes/collision/link6.vhacd.08.obj" />
      </geometry>
      <material name="panda_white" />
    </collision>
  <collision>
      <geometry>
        <mesh filename="hd_meshes/collision/link6.vhacd.09.obj" />
      </geometry>
      <material name="panda_white" />
    </collision>
  <collision>
      <geometry>
        <mesh filename="hd_meshes/collision/link6.vhacd.10.obj" />
      </geometry>
      <material name="panda_white" />
    </collision>
  <collision>
      <geometry>
        <mesh filename="hd_meshes/collision/link6.vhacd.11.obj" />
      </geometry>
      <material name="panda_white" />
    </collision>
  <collision>
      <geometry>
        <mesh filename="hd_meshes/collision/link6.vhacd.12.obj" />
      </geometry>
      <material name="panda_white" />
    </collision>
  <collision>
      <geometry>
        <mesh filename="hd_meshes/collision/link6.vhacd.13.obj" />
      </geometry>
      <material name="panda_white" />
    </collision>
  <collision>
      <geometry>
        <mesh filename="hd_meshes/collision/link6.vhacd.14.obj" />
      </geometry>
      <material name="panda_white" />
    </collision>
  <collision>
      <geometry>
        <mesh filename="hd_meshes/collision/link6.vhacd.15.obj" />
      </geometry>
      <material name="panda_white" />
    </collision>
  <collision>
      <geometry>
        <mesh filename="hd_meshes/collision/link6.vhacd.16.obj" />
      </geometry>
      <material name="panda_white" />
    </collision>
  <collision>
      <geometry>
        <mesh filename="hd_meshes/collision/link6.vhacd.17.obj" />
      </geometry>
      <material name="panda_white" />
    </collision>
  <collision>
      <geometry>
        <mesh filename="hd_meshes/collision/link6.vhacd.18.obj" />
      </geometry>
      <material name="panda_white" />
    </collision>
  <collision>
      <geometry>
        <mesh filename="hd_meshes/collision/link6.vhacd.19.obj" />
      </geometry>
      <material name="panda_white" />
    </collision>
  <collision>
      <geometry>
        <mesh filename="hd_meshes/collision/link6.vhacd.20.obj" />
      </geometry>
      <material name="panda_white" />
    </collision>
  <collision>
      <geometry>
        <mesh filename="hd_meshes/collision/link6.vhacd.21.obj" />
      </geometry>
      <material name="panda_white" />
    </collision>
  <collision>
      <geometry>
        <mesh filename="hd_meshes/collision/link6.vhacd.22.obj" />
      </geometry>
      <material name="panda_white" />
    </collision>
  <collision>
      <geometry>
        <mesh filename="hd_meshes/collision/link6.vhacd.23.obj" />
      </geometry>
      <material name="panda_white" />
    </collision>
  <collision>
      <geometry>
        <mesh filename="hd_meshes/collision/link6.vhacd.24.obj" />
      </geometry>
      <material name="panda_white" />
    </collision>
  </link>
  <joint name="panda_joint6" type="revolute">
    <safety_controller k_position="100.0" k_velocity="40.0" soft_lower_limit="-0.0175" soft_upper_limit="3.7525" />
    <origin rpy="1.57079632679 0 0" xyz="0 0 0" />
    <parent link="panda_link5" />
    <child link="panda_link6" />
    <axis xyz="0 0 1" />
    <limit effort="12" lower="-0.0175" upper="3.7525" velocity="2.6100" />
  </joint>
  <link name="panda_link7">
  	<inertial>
      <origin rpy="0 0 0" xyz="0 0 0.08" />
       <mass value=".2" />
       <inertia ixx="0.1" ixy="0" ixz="0" iyy="0.1" iyz="0" izz="0.1" />
    </inertial>
    <visual>
      <geometry>
        <mesh filename="hd_meshes/visual/link7.dae" />
      </geometry>
      <material name="panda_white" />
    </visual>
    <collision>
      <geometry>
        <mesh filename="hd_meshes/collision/link7.vhacd.00.obj" />
      </geometry>
      <material name="panda_white" />
    </collision>
  <collision>
      <geometry>
        <mesh filename="hd_meshes/collision/link7.vhacd.01.obj" />
      </geometry>
      <material name="panda_white" />
    </collision>
  <collision>
      <geometry>
        <mesh filename="hd_meshes/collision/link7.vhacd.02.obj" />
      </geometry>
      <material name="panda_white" />
    </collision>
  <collision>
      <geometry>
        <mesh filename="hd_meshes/collision/link7.vhacd.03.obj" />
      </geometry>
      <material name="panda_white" />
    </collision>
  <collision>
      <geometry>
        <mesh filename="hd_meshes/collision/link7.vhacd.04.obj" />
      </geometry>
      <material name="panda_white" />
    </collision>
  <collision>
      <geometry>
        <mesh filename="hd_meshes/collision/link7.vhacd.05.obj" />
      </geometry>
      <material name="panda_white" />
    </collision>
  <collision>
      <geometry>
        <mesh filename="hd_meshes/collision/link7.vhacd.06.obj" />
      </geometry>
      <material name="panda_white" />
    </collision>
  <collision>
      <geometry>
        <mesh filename="hd_meshes/collision/link7.vhacd.07.obj" />
      </geometry>
      <material name="panda_white" />
    </collision>
  <collision>
      <geometry>
        <mesh filename="hd_meshes/collision/link7.vhacd.08.obj" />
      </geometry>
      <material name="panda_white" />
    </collision>
  <collision>
      <geometry>
        <mesh filename="hd_meshes/collision/link7.vhacd.09.obj" />
      </geometry>
      <material name="panda_white" />
    </collision>
  <collision>
      <geometry>
        <mesh filename="hd_meshes/collision/link7.vhacd.10.obj" />
      </geometry>
      <material name="panda_white" />
    </collision>
  </link>
  <joint name="panda_joint7" type="revolute">
    <safety_controller k_position="100.0" k_velocity="40.0" soft_lower_limit="-2.8973" soft_upper_limit="2.8973" />
    <origin rpy="1.57079632679 0 0" xyz="0.088 0 0" />
    <parent link="panda_link6" />
    <child link="panda_link7" />
    <axis xyz="0 0 1" />
    <limit effort="12" lower="-2.8973" upper="2.8973" velocity="2.6100" />
  </joint>
  <link name="panda_link8">
  	 <inertial>
      <origin rpy="0 0 0" xyz="0 0 0" />
       <mass value="0.0" />
       <inertia ixx="0.1" ixy="0" ixz="0" iyy="0.1" iyz="0" izz="0.1" />
    </inertial>
  </link>
  <joint name="panda_joint8" type="fixed">
    <origin rpy="0 0 0" xyz="0 0 0.107" />
    <parent link="panda_link7" />
    <child link="panda_link8" />
    <axis xyz="0 0 0" />
  </joint>
  <link name="right_gripper">
    <inertial>

      <mass value="0.01" />
      <inertia ixx="0.0001" ixy="0.0" ixz="0.0" iyy="0.0001" iyz="0.0" izz="0.0001" />
      <origin rpy="0 0 0" xyz="0 0 0" />
    </inertial>
  </link>
  <joint name="right_gripper" type="fixed">
    <origin rpy="0 0 2.35619449019" xyz="0 0 0.1" />
      <axis xyz="0 0 1" />
    <parent link="panda_link8" />
    <child link="right_gripper" />
  </joint>
</robot>
